Workbook

Sheet דוגמא
C4: סיור בוקר 07:00-15:00 | I4: כרמל א | O4: חפ"ק | U4: ש.ג.
C5: שם: | D5: פלאפון: | E5: מ.א. | F5: תפקיד: | I5: שם: | J5: פלאפון: | K5: מ.א. | L5: תפקיד: | O5: שם: | P5: פלאפון: | Q5: מ.א. | R5: תפקיד: | U5: שם: | V5: פלאפון: | W5: מ.א. | X5: תפקיד:
D6: =_xlfn.SINGLE(_xlfn.IFNA(VLOOKUP($C6,'פרטים אישיים'!$D$4:$G$100,2,FALSE),"")) | E6: =_xlfn.SINGLE(_xlfn.IFNA(VLOOKUP($C6,'פרטים אישיים'!$D$4:$G$100,3,FALSE),"")) | F6: =_xlfn.SINGLE(_xlfn.IFNA(VLOOKUP($C6,'פרטים אישיים'!$D$4:$G$100,4,FALSE),"")) | J6: =_xlfn.SINGLE(_xlfn.IFNA(VLOOKUP($I6,'פרטים אישיים'!$D$4:$G$100,2,FALSE),"")) | K6: =_xlfn.SINGLE(_xlfn.IFNA(VLOOKUP($I6,'פרטים אישיים'!$D$4:$G$100,3,FALSE),"")) | L6: =_xlfn.SINGLE(_xlfn.IFNA(VLOOKUP($I6,'פרטים אישיים'!$D$4:$G$100,4,FALSE),"")) | P6: =_xlfn.SINGLE(_xlfn.IFNA(VLOOKUP($O6,'פרטים אישיים'!$D$4:$G$100,2,FALSE),"")) | Q6: =_xlfn.SINGLE(_xlfn.IFNA(VLOOKUP($O6,'פרטים אישיים'!$D$4:$G$100,3,FALSE),"")) | R6: =_xlfn.SINGLE(_xlfn.IFNA(VLOOKUP($O6,'פרטים אישיים'!$D$4:$G$100,4,FALSE),"")) | T6: 46082 | V6: =_xlfn.SINGLE(_xlfn.IFNA(VLOOKUP($U6,'פרטים אישיים'!$D$4:$G$100,2,FALSE),"")) | W6: =_xlfn.SINGLE(_xlfn.IFNA(VLOOKUP($U6,'פרטים אישיים'!$D$4:$G$100,3,FALSE),"")) | X6: =_xlfn.SINGLE(_xlfn.IFNA(VLOOKUP($U6,'פרטים אישיים'!$D$4:$G$100,4,FALSE),""))
D7: =_xlfn.SINGLE(_xlfn.IFNA(VLOOKUP($C7,'פרטים אישיים'!$D$4:$G$100,2,FALSE),"")) | E7: =_xlfn.SINGLE(_xlfn.IFNA(VLOOKUP($C7,'פרטים אישיים'!$D$4:$G$100,3,FALSE),"")) | F7: =_xlfn.SINGLE(_xlfn.IFNA(VLOOKUP($C7,'פרטים אישיים'!$D$4:$G$100,4,FALSE),"")) | J7: =_xlfn.SINGLE(_xlfn.IFNA(VLOOKUP($I7,'פרטים אישיים'!$D$4:$G$100,2,FALSE),"")) | K7: =_xlfn.SINGLE(_xlfn.IFNA(VLOOKUP($I7,'פרטים אישיים'!$D$4:$G$100,3,FALSE),"")) | L7: =_xlfn.SINGLE(_xlfn.IFNA(VLOOKUP($I7,'פרטים אישיים'!$D$4:$G$100,4,FALSE),"")) | P7: =_xlfn.SINGLE(_xlfn.IFNA(VLOOKUP($O7,'פרטים אישיים'!$D$4:$G$100,2,FALSE),"")) | Q7: =_xlfn.SINGLE(_xlfn.IFNA(VLOOKUP($O7,'פרטים אישיים'!$D$4:$G$100,3,FALSE),"")) | R7: =_xlfn.SINGLE(_xlfn.IFNA(VLOOKUP($O7,'פרטים אישיים'!$D$4:$G$100,4,FALSE),"")) | T7: 46145 | V7: =_xlfn.SINGLE(_xlfn.IFNA(VLOOKUP($U7,'פרטים אישיים'!$D$4:$G$100,2,FALSE),"")) | W7: =_xlfn.SINGLE(_xlfn.IFNA(VLOOKUP($U7,'פרטים אישיים'!$D$4:$G$100,3,FALSE),"")) | X7: =_xlfn.SINGLE(_xlfn.IFNA(VLOOKUP($U7,'פרטים אישיים'!$D$4:$G$100,4,FALSE),""))
D8: =_xlfn.SINGLE(_xlfn.IFNA(VLOOKUP($C8,'פרטים אישיים'!$D$4:$G$100,2,FALSE),"")) | E8: =_xlfn.SINGLE(_xlfn.IFNA(VLOOKUP($C8,'פרטים אישיים'!$D$4:$G$100,3,FALSE),"")) | F8: =_xlfn.SINGLE(_xlfn.IFNA(VLOOKUP($C8,'פרטים אישיים'!$D$4:$G$100,4,FALSE),"")) | J8: =_xlfn.SINGLE(_xlfn.IFNA(VLOOKUP($I8,'פרטים אישיים'!$D$4:$G$100,2,FALSE),"")) | K8: =_xlfn.SINGLE(_xlfn.IFNA(VLOOKUP($I8,'פרטים אישיים'!$D$4:$G$100,3,FALSE),"")) | L8: =_xlfn.SINGLE(_xlfn.IFNA(VLOOKUP($I8,'פרטים אישיים'!$D$4:$G$100,4,FALSE),"")) | P8: =_xlfn.SINGLE(_xlfn.IFNA(VLOOKUP($O8,'פרטים אישיים'!$D$4:$G$100,2,FALSE),"")) | Q8: =_xlfn.SINGLE(_xlfn.IFNA(VLOOKUP($O8,'פרטים אישיים'!$D$4:$G$100,3,FALSE),"")) | R8: =_xlfn.SINGLE(_xlfn.IFNA(VLOOKUP($O8,'פרטים אישיים'!$D$4:$G$100,4,FALSE),"")) | T8: 46208 | V8: =_xlfn.SINGLE(_xlfn.IFNA(VLOOKUP($U8,'פרטים אישיים'!$D$4:$G$100,2,FALSE),"")) | W8: =_xlfn.SINGLE(_xlfn.IFNA(VLOOKUP($U8,'פרטים אישיים'!$D$4:$G$100,3,FALSE),"")) | X8: =_xlfn.SINGLE(_xlfn.IFNA(VLOOKUP($U8,'פרטים אישיים'!$D$4:$G$100,4,FALSE),""))
J9: =_xlfn.SINGLE(_xlfn.IFNA(VLOOKUP($I9,'פרטים אישיים'!$D$4:$G$100,2,FALSE),"")) | K9: =_xlfn.SINGLE(_xlfn.IFNA(VLOOKUP($I9,'פרטים אישיים'!$D$4:$G$100,3,FALSE),"")) | L9: =_xlfn.SINGLE(_xlfn.IFNA(VLOOKUP($I9,'פרטים אישיים'!$D$4:$G$100,4,FALSE),"")) | P9: =_xlfn.SINGLE(_xlfn.IFNA(VLOOKUP($O9,'פרטים אישיים'!$D$4:$G$100,2,FALSE),"")) | Q9: =_xlfn.SINGLE(_xlfn.IFNA(VLOOKUP($O9,'פרטים אישיים'!$D$4:$G$100,3,FALSE),"")) | R9: =_xlfn.SINGLE(_xlfn.IFNA(VLOOKUP($O9,'פרטים אישיים'!$D$4:$G$100,4,FALSE),"")) | V9: =_xlfn.SINGLE(_xlfn.IFNA(VLOOKUP($U9,'פרטים אישיים'!$D$4:$G$100,2,FALSE),"")) | W9: =_xlfn.SINGLE(_xlfn.IFNA(VLOOKUP($U9,'פרטים אישיים'!$D$4:$G$100,3,FALSE),"")) | X9: =_xlfn.SINGLE(_xlfn.IFNA(VLOOKUP($U9,'פרטים אישיים'!$D$4:$G$100,4,FALSE),""))
J10: =_xlfn.SINGLE(_xlfn.IFNA(VLOOKUP($I10,'פרטים אישיים'!$D$4:$G$100,2,FALSE),"")) | K10: =_xlfn.SINGLE(_xlfn.IFNA(VLOOKUP($I10,'פרטים אישיים'!$D$4:$G$100,3,FALSE),"")) | L10: =_xlfn.SINGLE(_xlfn.IFNA(VLOOKUP($I10,'פרטים אישיים'!$D$4:$G$100,4,FALSE),"")) | S10: [מחר בבוקר] | T10: 05-07 (בונקר) | V10: =_xlfn.SINGLE(_xlfn.IFNA(VLOOKUP($U10,'פרטים אישיים'!$D$4:$G$100,2,FALSE),"")) | W10: =_xlfn.SINGLE(_xlfn.IFNA(VLOOKUP($U10,'פרטים אישיים'!$D$4:$G$100,3,FALSE),"")) | X10: =_xlfn.SINGLE(_xlfn.IFNA(VLOOKUP($U10,'פרטים אישיים'!$D$4:$G$100,4,FALSE),""))
C11: סיור ערב 15:00-23:00 | J11: =_xlfn.SINGLE(_xlfn.IFNA(VLOOKUP($I11,'פרטים אישיים'!$D$4:$G$100,2,FALSE),"")) | K11: =_xlfn.SINGLE(_xlfn.IFNA(VLOOKUP($I11,'פרטים אישיים'!$D$4:$G$100,3,FALSE),"")) | L11: =_xlfn.SINGLE(_xlfn.IFNA(VLOOKUP($I11,'פרטים אישיים'!$D$4:$G$100,4,FALSE),"")) | T11: 46272 | V11: =_xlfn.SINGLE(_xlfn.IFNA(VLOOKUP($U11,'פרטים אישיים'!$D$4:$G$100,2,FALSE),"")) | W11: =_xlfn.SINGLE(_xlfn.IFNA(VLOOKUP($U11,'פרטים אישיים'!$D$4:$G$100,3,FALSE),"")) | X11: =_xlfn.SINGLE(_xlfn.IFNA(VLOOKUP($U11,'פרטים אישיים'!$D$4:$G$100,4,FALSE),""))
C12: שם: | D12: פלאפון: | E12: מ.א. | F12: תפקיד: | J12: =_xlfn.SINGLE(_xlfn.IFNA(VLOOKUP($I12,'פרטים אישיים'!$D$4:$G$100,2,FALSE),"")) | K12: =_xlfn.SINGLE(_xlfn.IFNA(VLOOKUP($I12,'פרטים אישיים'!$D$4:$G$100,3,FALSE),"")) | L12: =_xlfn.SINGLE(_xlfn.IFNA(VLOOKUP($I12,'פרטים אישיים'!$D$4:$G$100,4,FALSE),"")) | T12: 46335 | V12: =_xlfn.SINGLE(_xlfn.IFNA(VLOOKUP($U12,'פרטים אישיים'!$D$4:$G$100,2,FALSE),"")) | W12: =_xlfn.SINGLE(_xlfn.IFNA(VLOOKUP($U12,'פרטים אישיים'!$D$4:$G$100,3,FALSE),"")) | X12: =_xlfn.SINGLE(_xlfn.IFNA(VLOOKUP($U12,'פרטים אישיים'!$D$4:$G$100,4,FALSE),""))
D13: =_xlfn.SINGLE(_xlfn.IFNA(VLOOKUP($C13,'פרטים אישיים'!$D$4:$G$100,2,FALSE),"")) | E13: =_xlfn.SINGLE(_xlfn.IFNA(VLOOKUP($C13,'פרטים אישיים'!$D$4:$G$100,3,FALSE),"")) | F13: =_xlfn.SINGLE(_xlfn.IFNA(VLOOKUP($C13,'פרטים אישיים'!$D$4:$G$100,4,FALSE),"")) | J13: =_xlfn.SINGLE(_xlfn.IFNA(VLOOKUP($I13,'פרטים אישיים'!$D$4:$G$100,2,FALSE),"")) | K13: =_xlfn.SINGLE(_xlfn.IFNA(VLOOKUP($I13,'פרטים אישיים'!$D$4:$G$100,3,FALSE),"")) | L13: =_xlfn.SINGLE(_xlfn.IFNA(VLOOKUP($I13,'פרטים אישיים'!$D$4:$G$100,4,FALSE),"")) | O13: גרשון | T13: 11-13 | V13: =_xlfn.SINGLE(_xlfn.IFNA(VLOOKUP($U13,'פרטים אישיים'!$D$4:$G$100,2,FALSE),"")) | W13: =_xlfn.SINGLE(_xlfn.IFNA(VLOOKUP($U13,'פרטים אישיים'!$D$4:$G$100,3,FALSE),"")) | X13: =_xlfn.SINGLE(_xlfn.IFNA(VLOOKUP($U13,'פרטים אישיים'!$D$4:$G$100,4,FALSE),""))
D14: =_xlfn.SINGLE(_xlfn.IFNA(VLOOKUP($C14,'פרטים אישיים'!$D$4:$G$100,2,FALSE),"")) | E14: =_xlfn.SINGLE(_xlfn.IFNA(VLOOKUP($C14,'פרטים אישיים'!$D$4:$G$100,3,FALSE),"")) | F14: =_xlfn.SINGLE(_xlfn.IFNA(VLOOKUP($C14,'פרטים אישיים'!$D$4:$G$100,4,FALSE),"")) | O14: שם: | P14: פלאפון: | Q14: מ.א. | R14: תפקיד:
D15: =_xlfn.SINGLE(_xlfn.IFNA(VLOOKUP($C15,'פרטים אישיים'!$D$4:$G$100,2,FALSE),"")) | E15: =_xlfn.SINGLE(_xlfn.IFNA(VLOOKUP($C15,'פרטים אישיים'!$D$4:$G$100,3,FALSE),"")) | F15: =_xlfn.SINGLE(_xlfn.IFNA(VLOOKUP($C15,'פרטים אישיים'!$D$4:$G$100,4,FALSE),"")) | P15: =_xlfn.SINGLE(_xlfn.IFNA(VLOOKUP($O15,'פרטים אישיים'!$D$4:$G$100,2,FALSE),"")) | Q15: =_xlfn.SINGLE(_xlfn.IFNA(VLOOKUP($O15,'פרטים אישיים'!$D$4:$G$100,3,FALSE),"")) | R15: =_xlfn.SINGLE(_xlfn.IFNA(VLOOKUP($O15,'פרטים אישיים'!$D$4:$G$100,4,FALSE),""))
I16: כרמל ב | P16: =_xlfn.SINGLE(_xlfn.IFNA(VLOOKUP($O16,'פרטים אישיים'!$D$4:$G$100,2,FALSE),"")) | Q16: =_xlfn.SINGLE(_xlfn.IFNA(VLOOKUP($O16,'פרטים אישיים'!$D$4:$G$100,3,FALSE),"")) | R16: =_xlfn.SINGLE(_xlfn.IFNA(VLOOKUP($O16,'פרטים אישיים'!$D$4:$G$100,4,FALSE),""))
I17: שם: | J17: פלאפון: | K17: מ.א. | L17: תפקיד: | P17: =_xlfn.SINGLE(_xlfn.IFNA(VLOOKUP($O17,'פרטים אישיים'!$D$4:$G$100,2,FALSE),"")) | Q17: =_xlfn.SINGLE(_xlfn.IFNA(VLOOKUP($O17,'פרטים אישיים'!$D$4:$G$100,3,FALSE),"")) | R17: =_xlfn.SINGLE(_xlfn.IFNA(VLOOKUP($O17,'פרטים אישיים'!$D$4:$G$100,4,FALSE),"")) | U17: תורנים
C18: סיור לילה 23:00-07:00 | J18: =_xlfn.SINGLE(_xlfn.IFNA(VLOOKUP($I18,'פרטים אישיים'!$D$4:$G$100,2,FALSE),"")) | K18: =_xlfn.SINGLE(_xlfn.IFNA(VLOOKUP($I18,'פרטים אישיים'!$D$4:$G$100,3,FALSE),"")) | L18: =_xlfn.SINGLE(_xlfn.IFNA(VLOOKUP($I18,'פרטים אישיים'!$D$4:$G$100,4,FALSE),"")) | P18: =_xlfn.SINGLE(_xlfn.IFNA(VLOOKUP($O18,'פרטים אישיים'!$D$4:$G$100,2,FALSE),"")) | Q18: =_xlfn.SINGLE(_xlfn.IFNA(VLOOKUP($O18,'פרטים אישיים'!$D$4:$G$100,3,FALSE),"")) | R18: =_xlfn.SINGLE(_xlfn.IFNA(VLOOKUP($O18,'פרטים אישיים'!$D$4:$G$100,4,FALSE),"")) | U18: שם: | V18: פלאפון: | W18: מ.א. | X18: תפקיד:
C19: שם: | D19: פלאפון: | E19: מ.א. | F19: תפקיד: | J19: =_xlfn.SINGLE(_xlfn.IFNA(VLOOKUP($I19,'פרטים אישיים'!$D$4:$G$100,2,FALSE),"")) | K19: =_xlfn.SINGLE(_xlfn.IFNA(VLOOKUP($I19,'פרטים אישיים'!$D$4:$G$100,3,FALSE),"")) | L19: =_xlfn.SINGLE(_xlfn.IFNA(VLOOKUP($I19,'פרטים אישיים'!$D$4:$G$100,4,FALSE),"")) | P19: =_xlfn.SINGLE(_xlfn.IFNA(VLOOKUP($O19,'פרטים אישיים'!$D$4:$G$100,2,FALSE),"")) | Q19: =_xlfn.SINGLE(_xlfn.IFNA(VLOOKUP($O19,'פרטים אישיים'!$D$4:$G$100,3,FALSE),"")) | R19: =_xlfn.SINGLE(_xlfn.IFNA(VLOOKUP($O19,'פרטים אישיים'!$D$4:$G$100,4,FALSE),"")) | T19: מטבח: | V19: =_xlfn.SINGLE(_xlfn.IFNA(VLOOKUP($U19,'פרטים אישיים'!$D$4:$G$100,2,FALSE),"")) | W19: =_xlfn.SINGLE(_xlfn.IFNA(VLOOKUP($U19,'פרטים אישיים'!$D$4:$G$100,3,FALSE),"")) | X19: =_xlfn.SINGLE(_xlfn.IFNA(VLOOKUP($U19,'פרטים אישיים'!$D$4:$G$100,4,FALSE),""))
D20: =_xlfn.SINGLE(_xlfn.IFNA(VLOOKUP($C20,'פרטים אישיים'!$D$4:$G$100,2,FALSE),"")) | E20: =_xlfn.SINGLE(_xlfn.IFNA(VLOOKUP($C20,'פרטים אישיים'!$D$4:$G$100,3,FALSE),"")) | F20: =_xlfn.SINGLE(_xlfn.IFNA(VLOOKUP($C20,'פרטים אישיים'!$D$4:$G$100,4,FALSE),"")) | J20: =_xlfn.SINGLE(_xlfn.IFNA(VLOOKUP($I20,'פרטים אישיים'!$D$4:$G$100,2,FALSE),"")) | K20: =_xlfn.SINGLE(_xlfn.IFNA(VLOOKUP($I20,'פרטים אישיים'!$D$4:$G$100,3,FALSE),"")) | L20: =_xlfn.SINGLE(_xlfn.IFNA(VLOOKUP($I20,'פרטים אישיים'!$D$4:$G$100,4,FALSE),"")) | P20: =_xlfn.SINGLE(_xlfn.IFNA(VLOOKUP($O20,'פרטים אישיים'!$D$4:$G$100,2,FALSE),"")) | Q20: =_xlfn.SINGLE(_xlfn.IFNA(VLOOKUP($O20,'פרטים אישיים'!$D$4:$G$100,3,FALSE),"")) | R20: =_xlfn.SINGLE(_xlfn.IFNA(VLOOKUP($O20,'פרטים אישיים'!$D$4:$G$100,4,FALSE),"")) | T20: מפלג: | V20: =_xlfn.SINGLE(_xlfn.IFNA(VLOOKUP($U20,'פרטים אישיים'!$D$4:$G$100,2,FALSE),"")) | W20: =_xlfn.SINGLE(_xlfn.IFNA(VLOOKUP($U20,'פרטים אישיים'!$D$4:$G$100,3,FALSE),"")) | X20: =_xlfn.SINGLE(_xlfn.IFNA(VLOOKUP($U20,'פרטים אישיים'!$D$4:$G$100,4,FALSE),""))
D21: =_xlfn.SINGLE(_xlfn.IFNA(VLOOKUP($C21,'פרטים אישיים'!$D$4:$G$100,2,FALSE),"")) | E21: =_xlfn.SINGLE(_xlfn.IFNA(VLOOKUP($C21,'פרטים אישיים'!$D$4:$G$100,3,FALSE),"")) | F21: =_xlfn.SINGLE(_xlfn.IFNA(VLOOKUP($C21,'פרטים אישיים'!$D$4:$G$100,4,FALSE),"")) | J21: =_xlfn.SINGLE(_xlfn.IFNA(VLOOKUP($I21,'פרטים אישיים'!$D$4:$G$100,2,FALSE),"")) | K21: =_xlfn.SINGLE(_xlfn.IFNA(VLOOKUP($I21,'פרטים אישיים'!$D$4:$G$100,3,FALSE),"")) | L21: =_xlfn.SINGLE(_xlfn.IFNA(VLOOKUP($I21,'פרטים אישיים'!$D$4:$G$100,4,FALSE),""))
D22: =_xlfn.SINGLE(_xlfn.IFNA(VLOOKUP($C22,'פרטים אישיים'!$D$4:$G$100,2,FALSE),"")) | E22: =_xlfn.SINGLE(_xlfn.IFNA(VLOOKUP($C22,'פרטים אישיים'!$D$4:$G$100,3,FALSE),"")) | F22: =_xlfn.SINGLE(_xlfn.IFNA(VLOOKUP($C22,'פרטים אישיים'!$D$4:$G$100,4,FALSE),""))

Sheet שבת, 21.02
C4: סיור בוקר 07:00-15:00 | I4: כרמל א | O4: חפ"ק | U4: ש.ג.
C5: שם: | D5: פלאפון: | E5: מ.א. | F5: תפקיד: | I5: שם: | J5: פלאפון: | K5: מ.א. | L5: תפקיד: | O5: שם: | P5: פלאפון: | Q5: מ.א. | R5: תפקיד: | U5: שם: | V5: פלאפון: | W5: מ.א. | X5: תפקיד:
D6: =_xlfn.SINGLE(_xlfn.IFNA(VLOOKUP($C6,'פרטים אישיים'!$D$4:$G$100,2,FALSE),"")) | E6: =_xlfn.SINGLE(_xlfn.IFNA(VLOOKUP($C6,'פרטים אישיים'!$D$4:$G$100,3,FALSE),"")) | F6: =_xlfn.SINGLE(_xlfn.IFNA(VLOOKUP($C6,'פרטים אישיים'!$D$4:$G$100,4,FALSE),"")) | I6: מאיר יוסט | J6: =_xlfn.SINGLE(_xlfn.IFNA(VLOOKUP($I6,'פרטים אישיים'!$D$4:$G$100,2,FALSE),"")) -> 058-6644228 | K6: =_xlfn.SINGLE(_xlfn.IFNA(VLOOKUP($I6,'פרטים אישיים'!$D$4:$G$100,3,FALSE),"")) -> 8264943 | L6: =_xlfn.SINGLE(_xlfn.IFNA(VLOOKUP($I6,'פרטים אישיים'!$D$4:$G$100,4,FALSE),"")) -> מ"מ | P6: =_xlfn.SINGLE(_xlfn.IFNA(VLOOKUP($O6,'פרטים אישיים'!$D$4:$G$100,2,FALSE),"")) | Q6: =_xlfn.SINGLE(_xlfn.IFNA(VLOOKUP($O6,'פרטים אישיים'!$D$4:$G$100,3,FALSE),"")) | R6: =_xlfn.SINGLE(_xlfn.IFNA(VLOOKUP($O6,'פרטים אישיים'!$D$4:$G$100,4,FALSE),"")) | T6: 46082 | V6: =_xlfn.SINGLE(_xlfn.IFNA(VLOOKUP($U6,'פרטים אישיים'!$D$4:$G$100,2,FALSE),"")) | W6: =_xlfn.SINGLE(_xlfn.IFNA(VLOOKUP($U6,'פרטים אישיים'!$D$4:$G$100,3,FALSE),"")) | X6: =_xlfn.SINGLE(_xlfn.IFNA(VLOOKUP($U6,'פרטים אישיים'!$D$4:$G$100,4,FALSE),""))
D7: =_xlfn.SINGLE(_xlfn.IFNA(VLOOKUP($C7,'פרטים אישיים'!$D$4:$G$100,2,FALSE),"")) | E7: =_xlfn.SINGLE(_xlfn.IFNA(VLOOKUP($C7,'פרטים אישיים'!$D$4:$G$100,3,FALSE),"")) | F7: =_xlfn.SINGLE(_xlfn.IFNA(VLOOKUP($C7,'פרטים אישיים'!$D$4:$G$100,4,FALSE),"")) | I7: נתנאל שלום | J7: =_xlfn.SINGLE(_xlfn.IFNA(VLOOKUP($I7,'פרטים אישיים'!$D$4:$G$100,2,FALSE),"")) -> 054-6406758 | K7: =_xlfn.SINGLE(_xlfn.IFNA(VLOOKUP($I7,'פרטים אישיים'!$D$4:$G$100,3,FALSE),"")) -> 8459664 | L7: =_xlfn.SINGLE(_xlfn.IFNA(VLOOKUP($I7,'פרטים אישיים'!$D$4:$G$100,4,FALSE),"")) -> לוחם | P7: =_xlfn.SINGLE(_xlfn.IFNA(VLOOKUP($O7,'פרטים אישיים'!$D$4:$G$100,2,FALSE),"")) | Q7: =_xlfn.SINGLE(_xlfn.IFNA(VLOOKUP($O7,'פרטים אישיים'!$D$4:$G$100,3,FALSE),"")) | R7: =_xlfn.SINGLE(_xlfn.IFNA(VLOOKUP($O7,'פרטים אישיים'!$D$4:$G$100,4,FALSE),"")) | T7: 46145 | V7: =_xlfn.SINGLE(_xlfn.IFNA(VLOOKUP($U7,'פרטים אישיים'!$D$4:$G$100,2,FALSE),"")) | W7: =_xlfn.SINGLE(_xlfn.IFNA(VLOOKUP($U7,'פרטים אישיים'!$D$4:$G$100,3,FALSE),"")) | X7: =_xlfn.SINGLE(_xlfn.IFNA(VLOOKUP($U7,'פרטים אישיים'!$D$4:$G$100,4,FALSE),""))
D8: =_xlfn.SINGLE(_xlfn.IFNA(VLOOKUP($C8,'פרטים אישיים'!$D$4:$G$100,2,FALSE),"")) | E8: =_xlfn.SINGLE(_xlfn.IFNA(VLOOKUP($C8,'פרטים אישיים'!$D$4:$G$100,3,FALSE),"")) | F8: =_xlfn.SINGLE(_xlfn.IFNA(VLOOKUP($C8,'פרטים אישיים'!$D$4:$G$100,4,FALSE),"")) | I8: יאיר שוייצר | J8: =_xlfn.SINGLE(_xlfn.IFNA(VLOOKUP($I8,'פרטים אישיים'!$D$4:$G$100,2,FALSE),"")) -> 052-3909856 | K8: =_xlfn.SINGLE(_xlfn.IFNA(VLOOKUP($I8,'פרטים אישיים'!$D$4:$G$100,3,FALSE),"")) -> 8233128 | L8: =_xlfn.SINGLE(_xlfn.IFNA(VLOOKUP($I8,'פרטים אישיים'!$D$4:$G$100,4,FALSE),"")) -> קלע | P8: =_xlfn.SINGLE(_xlfn.IFNA(VLOOKUP($O8,'פרטים אישיים'!$D$4:$G$100,2,FALSE),"")) | Q8: =_xlfn.SINGLE(_xlfn.IFNA(VLOOKUP($O8,'פרטים אישיים'!$D$4:$G$100,3,FALSE),"")) | R8: =_xlfn.SINGLE(_xlfn.IFNA(VLOOKUP($O8,'פרטים אישיים'!$D$4:$G$100,4,FALSE),"")) | T8: 46208 | V8: =_xlfn.SINGLE(_xlfn.IFNA(VLOOKUP($U8,'פרטים אישיים'!$D$4:$G$100,2,FALSE),"")) | W8: =_xlfn.SINGLE(_xlfn.IFNA(VLOOKUP($U8,'פרטים אישיים'!$D$4:$G$100,3,FALSE),"")) | X8: =_xlfn.SINGLE(_xlfn.IFNA(VLOOKUP($U8,'פרטים אישיים'!$D$4:$G$100,4,FALSE),""))
I9: אריאל וילנר | J9: =_xlfn.SINGLE(_xlfn.IFNA(VLOOKUP($I9,'פרטים אישיים'!$D$4:$G$100,2,FALSE),"")) -> 052-2456636 | K9: =_xlfn.SINGLE(_xlfn.IFNA(VLOOKUP($I9,'פרטים אישיים'!$D$4:$G$100,3,FALSE),"")) -> 8110205 | L9: =_xlfn.SINGLE(_xlfn.IFNA(VLOOKUP($I9,'פרטים אישיים'!$D$4:$G$100,4,FALSE),"")) -> לוחם | P9: =_xlfn.SINGLE(_xlfn.IFNA(VLOOKUP($O9,'פרטים אישיים'!$D$4:$G$100,2,FALSE),"")) | Q9: =_xlfn.SINGLE(_xlfn.IFNA(VLOOKUP($O9,'פרטים אישיים'!$D$4:$G$100,3,FALSE),"")) | R9: =_xlfn.SINGLE(_xlfn.IFNA(VLOOKUP($O9,'פרטים אישיים'!$D$4:$G$100,4,FALSE),"")) | V9: =_xlfn.SINGLE(_xlfn.IFNA(VLOOKUP($U9,'פרטים אישיים'!$D$4:$G$100,2,FALSE),"")) | W9: =_xlfn.SINGLE(_xlfn.IFNA(VLOOKUP($U9,'פרטים אישיים'!$D$4:$G$100,3,FALSE),"")) | X9: =_xlfn.SINGLE(_xlfn.IFNA(VLOOKUP($U9,'פרטים אישיים'!$D$4:$G$100,4,FALSE),""))
I10: אביתר בן-שושן | J10: =_xlfn.SINGLE(_xlfn.IFNA(VLOOKUP($I10,'פרטים אישיים'!$D$4:$G$100,2,FALSE),"")) -> 053-5251353 | K10: =_xlfn.SINGLE(_xlfn.IFNA(VLOOKUP($I10,'פרטים אישיים'!$D$4:$G$100,3,FALSE),"")) -> 8301564 | L10: =_xlfn.SINGLE(_xlfn.IFNA(VLOOKUP($I10,'פרטים אישיים'!$D$4:$G$100,4,FALSE),"")) -> לוחם | S10: [מחר בבוקר] | T10: 05-07 (בונקר) | V10: =_xlfn.SINGLE(_xlfn.IFNA(VLOOKUP($U10,'פרטים אישיים'!$D$4:$G$100,2,FALSE),"")) | W10: =_xlfn.SINGLE(_xlfn.IFNA(VLOOKUP($U10,'פרטים אישיים'!$D$4:$G$100,3,FALSE),"")) | X10: =_xlfn.SINGLE(_xlfn.IFNA(VLOOKUP($U10,'פרטים אישיים'!$D$4:$G$100,4,FALSE),""))
C11: סיור ערב 15:00-23:00 | I11: אוראל סמדג'ה | J11: =_xlfn.SINGLE(_xlfn.IFNA(VLOOKUP($I11,'פרטים אישיים'!$D$4:$G$100,2,FALSE),"")) -> 052-6226118 | K11: =_xlfn.SINGLE(_xlfn.IFNA(VLOOKUP($I11,'פרטים אישיים'!$D$4:$G$100,3,FALSE),"")) -> 8295723 | L11: =_xlfn.SINGLE(_xlfn.IFNA(VLOOKUP($I11,'פרטים אישיים'!$D$4:$G$100,4,FALSE),"")) -> לוחם | T11: 46272 | V11: =_xlfn.SINGLE(_xlfn.IFNA(VLOOKUP($U11,'פרטים אישיים'!$D$4:$G$100,2,FALSE),"")) | W11: =_xlfn.SINGLE(_xlfn.IFNA(VLOOKUP($U11,'פרטים אישיים'!$D$4:$G$100,3,FALSE),"")) | X11: =_xlfn.SINGLE(_xlfn.IFNA(VLOOKUP($U11,'פרטים אישיים'!$D$4:$G$100,4,FALSE),""))
C12: שם: | D12: פלאפון: | E12: מ.א. | F12: תפקיד: | I12: עומר חמו | J12: =_xlfn.SINGLE(_xlfn.IFNA(VLOOKUP($I12,'פרטים אישיים'!$D$4:$G$100,2,FALSE),"")) -> 053-3010189 | K12: =_xlfn.SINGLE(_xlfn.IFNA(VLOOKUP($I12,'פרטים אישיים'!$D$4:$G$100,3,FALSE),"")) -> 8401680 | L12: =_xlfn.SINGLE(_xlfn.IFNA(VLOOKUP($I12,'פרטים אישיים'!$D$4:$G$100,4,FALSE),"")) -> לוחם | T12: 46335 | V12: =_xlfn.SINGLE(_xlfn.IFNA(VLOOKUP($U12,'פרטים אישיים'!$D$4:$G$100,2,FALSE),"")) | W12: =_xlfn.SINGLE(_xlfn.IFNA(VLOOKUP($U12,'פרטים אישיים'!$D$4:$G$100,3,FALSE),"")) | X12: =_xlfn.SINGLE(_xlfn.IFNA(VLOOKUP($U12,'פרטים אישיים'!$D$4:$G$100,4,FALSE),""))
D13: =_xlfn.SINGLE(_xlfn.IFNA(VLOOKUP($C13,'פרטים אישיים'!$D$4:$G$100,2,FALSE),"")) | E13: =_xlfn.SINGLE(_xlfn.IFNA(VLOOKUP($C13,'פרטים אישיים'!$D$4:$G$100,3,FALSE),"")) | F13: =_xlfn.SINGLE(_xlfn.IFNA(VLOOKUP($C13,'פרטים אישיים'!$D$4:$G$100,4,FALSE),"")) | I13: גל יערי | J13: =_xlfn.SINGLE(_xlfn.IFNA(VLOOKUP($I13,'פרטים אישיים'!$D$4:$G$100,2,FALSE),"")) -> 050-4201499 | K13: =_xlfn.SINGLE(_xlfn.IFNA(VLOOKUP($I13,'פרטים אישיים'!$D$4:$G$100,3,FALSE),"")) -> 8712591 | L13: =_xlfn.SINGLE(_xlfn.IFNA(VLOOKUP($I13,'פרטים אישיים'!$D$4:$G$100,4,FALSE),"")) -> מטול | O13: גרשון | T13: 11-13 | V13: =_xlfn.SINGLE(_xlfn.IFNA(VLOOKUP($U13,'פרטים אישיים'!$D$4:$G$100,2,FALSE),"")) | W13: =_xlfn.SINGLE(_xlfn.IFNA(VLOOKUP($U13,'פרטים אישיים'!$D$4:$G$100,3,FALSE),"")) | X13: =_xlfn.SINGLE(_xlfn.IFNA(VLOOKUP($U13,'פרטים אישיים'!$D$4:$G$100,4,FALSE),""))
D14: =_xlfn.SINGLE(_xlfn.IFNA(VLOOKUP($C14,'פרטים אישיים'!$D$4:$G$100,2,FALSE),"")) | E14: =_xlfn.SINGLE(_xlfn.IFNA(VLOOKUP($C14,'פרטים אישיים'!$D$4:$G$100,3,FALSE),"")) | F14: =_xlfn.SINGLE(_xlfn.IFNA(VLOOKUP($C14,'פרטים אישיים'!$D$4:$G$100,4,FALSE),"")) | O14: שם: | P14: פלאפון: | Q14: מ.א. | R14: תפקיד:
D15: =_xlfn.SINGLE(_xlfn.IFNA(VLOOKUP($C15,'פרטים אישיים'!$D$4:$G$100,2,FALSE),"")) | E15: =_xlfn.SINGLE(_xlfn.IFNA(VLOOKUP($C15,'פרטים אישיים'!$D$4:$G$100,3,FALSE),"")) | F15: =_xlfn.SINGLE(_xlfn.IFNA(VLOOKUP($C15,'פרטים אישיים'!$D$4:$G$100,4,FALSE),"")) | P15: =_xlfn.SINGLE(_xlfn.IFNA(VLOOKUP($O15,'פרטים אישיים'!$D$4:$G$100,2,FALSE),"")) | Q15: =_xlfn.SINGLE(_xlfn.IFNA(VLOOKUP($O15,'פרטים אישיים'!$D$4:$G$100,3,FALSE),"")) | R15: =_xlfn.SINGLE(_xlfn.IFNA(VLOOKUP($O15,'פרטים אישיים'!$D$4:$G$100,4,FALSE),""))
I16: כרמל ב | P16: =_xlfn.SINGLE(_xlfn.IFNA(VLOOKUP($O16,'פרטים אישיים'!$D$4:$G$100,2,FALSE),"")) | Q16: =_xlfn.SINGLE(_xlfn.IFNA(VLOOKUP($O16,'פרטים אישיים'!$D$4:$G$100,3,FALSE),"")) | R16: =_xlfn.SINGLE(_xlfn.IFNA(VLOOKUP($O16,'פרטים אישיים'!$D$4:$G$100,4,FALSE),""))
I17: שם: | J17: פלאפון: | K17: מ.א. | L17: תפקיד: | P17: =_xlfn.SINGLE(_xlfn.IFNA(VLOOKUP($O17,'פרטים אישיים'!$D$4:$G$100,2,FALSE),"")) | Q17: =_xlfn.SINGLE(_xlfn.IFNA(VLOOKUP($O17,'פרטים אישיים'!$D$4:$G$100,3,FALSE),"")) | R17: =_xlfn.SINGLE(_xlfn.IFNA(VLOOKUP($O17,'פרטים אישיים'!$D$4:$G$100,4,FALSE),"")) | U17: תורנים
C18: סיור לילה 23:00-07:00 | J18: =_xlfn.SINGLE(_xlfn.IFNA(VLOOKUP($I18,'פרטים אישיים'!$D$4:$G$100,2,FALSE),"")) | K18: =_xlfn.SINGLE(_xlfn.IFNA(VLOOKUP($I18,'פרטים אישיים'!$D$4:$G$100,3,FALSE),"")) | L18: =_xlfn.SINGLE(_xlfn.IFNA(VLOOKUP($I18,'פרטים אישיים'!$D$4:$G$100,4,FALSE),"")) | P18: =_xlfn.SINGLE(_xlfn.IFNA(VLOOKUP($O18,'פרטים אישיים'!$D$4:$G$100,2,FALSE),"")) | Q18: =_xlfn.SINGLE(_xlfn.IFNA(VLOOKUP($O18,'פרטים אישיים'!$D$4:$G$100,3,FALSE),"")) | R18: =_xlfn.SINGLE(_xlfn.IFNA(VLOOKUP($O18,'פרטים אישיים'!$D$4:$G$100,4,FALSE),"")) | U18: שם: | V18: פלאפון: | W18: מ.א. | X18: תפקיד:
C19: שם: | D19: פלאפון: | E19: מ.א. | F19: תפקיד: | J19: =_xlfn.SINGLE(_xlfn.IFNA(VLOOKUP($I19,'פרטים אישיים'!$D$4:$G$100,2,FALSE),"")) | K19: =_xlfn.SINGLE(_xlfn.IFNA(VLOOKUP($I19,'פרטים אישיים'!$D$4:$G$100,3,FALSE),"")) | L19: =_xlfn.SINGLE(_xlfn.IFNA(VLOOKUP($I19,'פרטים אישיים'!$D$4:$G$100,4,FALSE),"")) | P19: =_xlfn.SINGLE(_xlfn.IFNA(VLOOKUP($O19,'פרטים אישיים'!$D$4:$G$100,2,FALSE),"")) | Q19: =_xlfn.SINGLE(_xlfn.IFNA(VLOOKUP($O19,'פרטים אישיים'!$D$4:$G$100,3,FALSE),"")) | R19: =_xlfn.SINGLE(_xlfn.IFNA(VLOOKUP($O19,'פרטים אישיים'!$D$4:$G$100,4,FALSE),"")) | T19: מטבח: | V19: =_xlfn.SINGLE(_xlfn.IFNA(VLOOKUP($U19,'פרטים אישיים'!$D$4:$G$100,2,FALSE),"")) | W19: =_xlfn.SINGLE(_xlfn.IFNA(VLOOKUP($U19,'פרטים אישיים'!$D$4:$G$100,3,FALSE),"")) | X19: =_xlfn.SINGLE(_xlfn.IFNA(VLOOKUP($U19,'פרטים אישיים'!$D$4:$G$100,4,FALSE),""))
D20: =_xlfn.SINGLE(_xlfn.IFNA(VLOOKUP($C20,'פרטים אישיים'!$D$4:$G$100,2,FALSE),"")) | E20: =_xlfn.SINGLE(_xlfn.IFNA(VLOOKUP($C20,'פרטים אישיים'!$D$4:$G$100,3,FALSE),"")) | F20: =_xlfn.SINGLE(_xlfn.IFNA(VLOOKUP($C20,'פרטים אישיים'!$D$4:$G$100,4,FALSE),"")) | J20: =_xlfn.SINGLE(_xlfn.IFNA(VLOOKUP($I20,'פרטים אישיים'!$D$4:$G$100,2,FALSE),"")) | K20: =_xlfn.SINGLE(_xlfn.IFNA(VLOOKUP($I20,'פרטים אישיים'!$D$4:$G$100,3,FALSE),"")) | L20: =_xlfn.SINGLE(_xlfn.IFNA(VLOOKUP($I20,'פרטים אישיים'!$D$4:$G$100,4,FALSE),"")) | P20: =_xlfn.SINGLE(_xlfn.IFNA(VLOOKUP($O20,'פרטים אישיים'!$D$4:$G$100,2,FALSE),"")) | Q20: =_xlfn.SINGLE(_xlfn.IFNA(VLOOKUP($O20,'פרטים אישיים'!$D$4:$G$100,3,FALSE),"")) | R20: =_xlfn.SINGLE(_xlfn.IFNA(VLOOKUP($O20,'פרטים אישיים'!$D$4:$G$100,4,FALSE),"")) | T20: מפלג: | V20: =_xlfn.SINGLE(_xlfn.IFNA(VLOOKUP($U20,'פרטים אישיים'!$D$4:$G$100,2,FALSE),"")) | W20: =_xlfn.SINGLE(_xlfn.IFNA(VLOOKUP($U20,'פרטים אישיים'!$D$4:$G$100,3,FALSE),"")) | X20: =_xlfn.SINGLE(_xlfn.IFNA(VLOOKUP($U20,'פרטים אישיים'!$D$4:$G$100,4,FALSE),""))
D21: =_xlfn.SINGLE(_xlfn.IFNA(VLOOKUP($C21,'פרטים אישיים'!$D$4:$G$100,2,FALSE),"")) | E21: =_xlfn.SINGLE(_xlfn.IFNA(VLOOKUP($C21,'פרטים אישיים'!$D$4:$G$100,3,FALSE),"")) | F21: =_xlfn.SINGLE(_xlfn.IFNA(VLOOKUP($C21,'פרטים אישיים'!$D$4:$G$100,4,FALSE),"")) | J21: =_xlfn.SINGLE(_xlfn.IFNA(VLOOKUP($I21,'פרטים אישיים'!$D$4:$G$100,2,FALSE),"")) | K21: =_xlfn.SINGLE(_xlfn.IFNA(VLOOKUP($I21,'פרטים אישיים'!$D$4:$G$100,3,FALSE),"")) | L21: =_xlfn.SINGLE(_xlfn.IFNA(VLOOKUP($I21,'פרטים אישיים'!$D$4:$G$100,4,FALSE),""))
D22: =_xlfn.SINGLE(_xlfn.IFNA(VLOOKUP($C22,'פרטים אישיים'!$D$4:$G$100,2,FALSE),"")) | E22: =_xlfn.SINGLE(_xlfn.IFNA(VLOOKUP($C22,'פרטים אישיים'!$D$4:$G$100,3,FALSE),"")) | F22: =_xlfn.SINGLE(_xlfn.IFNA(VLOOKUP($C22,'פרטים אישיים'!$D$4:$G$100,4,FALSE),""))

Sheet ראשון, 22.02
C4: סיור בוקר 07:00-15:00 | I4: כרמל א | O4: חפ"ק | U4: ש.ג.
C5: שם: | D5: פלאפון: | E5: מ.א. | F5: תפקיד: | I5: שם: | J5: פלאפון: | K5: מ.א. | L5: תפקיד: | O5: שם: | P5: פלאפון: | Q5: מ.א. | R5: תפקיד: | U5: שם: | V5: פלאפון: | W5: מ.א. | X5: תפקיד:
D6: =_xlfn.SINGLE(_xlfn.IFNA(VLOOKUP($C6,'פרטים אישיים'!$D$4:$G$100,2,FALSE),"")) | E6: =_xlfn.SINGLE(_xlfn.IFNA(VLOOKUP($C6,'פרטים אישיים'!$D$4:$G$100,3,FALSE),"")) | F6: =_xlfn.SINGLE(_xlfn.IFNA(VLOOKUP($C6,'פרטים אישיים'!$D$4:$G$100,4,FALSE),"")) | I6: יובל שרגאי | J6: =_xlfn.SINGLE(_xlfn.IFNA(VLOOKUP($I6,'פרטים אישיים'!$D$4:$G$100,2,FALSE),"")) -> 050-6422434 | K6: =_xlfn.SINGLE(_xlfn.IFNA(VLOOKUP($I6,'פרטים אישיים'!$D$4:$G$100,3,FALSE),"")) -> 8696787 | L6: =_xlfn.SINGLE(_xlfn.IFNA(VLOOKUP($I6,'פרטים אישיים'!$D$4:$G$100,4,FALSE),"")) -> 0 | P6: =_xlfn.SINGLE(_xlfn.IFNA(VLOOKUP($O6,'פרטים אישיים'!$D$4:$G$100,2,FALSE),"")) | Q6: =_xlfn.SINGLE(_xlfn.IFNA(VLOOKUP($O6,'פרטים אישיים'!$D$4:$G$100,3,FALSE),"")) | R6: =_xlfn.SINGLE(_xlfn.IFNA(VLOOKUP($O6,'פרטים אישיים'!$D$4:$G$100,4,FALSE),"")) | T6: 46082 | V6: =_xlfn.SINGLE(_xlfn.IFNA(VLOOKUP($U6,'פרטים אישיים'!$D$4:$G$100,2,FALSE),"")) | W6: =_xlfn.SINGLE(_xlfn.IFNA(VLOOKUP($U6,'פרטים אישיים'!$D$4:$G$100,3,FALSE),"")) | X6: =_xlfn.SINGLE(_xlfn.IFNA(VLOOKUP($U6,'פרטים אישיים'!$D$4:$G$100,4,FALSE),""))
D7: =_xlfn.SINGLE(_xlfn.IFNA(VLOOKUP($C7,'פרטים אישיים'!$D$4:$G$100,2,FALSE),"")) | E7: =_xlfn.SINGLE(_xlfn.IFNA(VLOOKUP($C7,'פרטים אישיים'!$D$4:$G$100,3,FALSE),"")) | F7: =_xlfn.SINGLE(_xlfn.IFNA(VLOOKUP($C7,'פרטים אישיים'!$D$4:$G$100,4,FALSE),"")) | J7: =_xlfn.SINGLE(_xlfn.IFNA(VLOOKUP($I7,'פרטים אישיים'!$D$4:$G$100,2,FALSE),"")) | K7: =_xlfn.SINGLE(_xlfn.IFNA(VLOOKUP($I7,'פרטים אישיים'!$D$4:$G$100,3,FALSE),"")) | L7: =_xlfn.SINGLE(_xlfn.IFNA(VLOOKUP($I7,'פרטים אישיים'!$D$4:$G$100,4,FALSE),"")) | P7: =_xlfn.SINGLE(_xlfn.IFNA(VLOOKUP($O7,'פרטים אישיים'!$D$4:$G$100,2,FALSE),"")) | Q7: =_xlfn.SINGLE(_xlfn.IFNA(VLOOKUP($O7,'פרטים אישיים'!$D$4:$G$100,3,FALSE),"")) | R7: =_xlfn.SINGLE(_xlfn.IFNA(VLOOKUP($O7,'פרטים אישיים'!$D$4:$G$100,4,FALSE),"")) | T7: 46145 | V7: =_xlfn.SINGLE(_xlfn.IFNA(VLOOKUP($U7,'פרטים אישיים'!$D$4:$G$100,2,FALSE),"")) | W7: =_xlfn.SINGLE(_xlfn.IFNA(VLOOKUP($U7,'פרטים אישיים'!$D$4:$G$100,3,FALSE),"")) | X7: =_xlfn.SINGLE(_xlfn.IFNA(VLOOKUP($U7,'פרטים אישיים'!$D$4:$G$100,4,FALSE),""))
D8: =_xlfn.SINGLE(_xlfn.IFNA(VLOOKUP($C8,'פרטים אישיים'!$D$4:$G$100,2,FALSE),"")) | E8: =_xlfn.SINGLE(_xlfn.IFNA(VLOOKUP($C8,'פרטים אישיים'!$D$4:$G$100,3,FALSE),"")) | F8: =_xlfn.SINGLE(_xlfn.IFNA(VLOOKUP($C8,'פרטים אישיים'!$D$4:$G$100,4,FALSE),"")) | J8: =_xlfn.SINGLE(_xlfn.IFNA(VLOOKUP($I8,'פרטים אישיים'!$D$4:$G$100,2,FALSE),"")) | K8: =_xlfn.SINGLE(_xlfn.IFNA(VLOOKUP($I8,'פרטים אישיים'!$D$4:$G$100,3,FALSE),"")) | L8: =_xlfn.SINGLE(_xlfn.IFNA(VLOOKUP($I8,'פרטים אישיים'!$D$4:$G$100,4,FALSE),"")) | P8: =_xlfn.SINGLE(_xlfn.IFNA(VLOOKUP($O8,'פרטים אישיים'!$D$4:$G$100,2,FALSE),"")) | Q8: =_xlfn.SINGLE(_xlfn.IFNA(VLOOKUP($O8,'פרטים אישיים'!$D$4:$G$100,3,FALSE),"")) | R8: =_xlfn.SINGLE(_xlfn.IFNA(VLOOKUP($O8,'פרטים אישיים'!$D$4:$G$100,4,FALSE),"")) | T8: 46208 | V8: =_xlfn.SINGLE(_xlfn.IFNA(VLOOKUP($U8,'פרטים אישיים'!$D$4:$G$100,2,FALSE),"")) | W8: =_xlfn.SINGLE(_xlfn.IFNA(VLOOKUP($U8,'פרטים אישיים'!$D$4:$G$100,3,FALSE),"")) | X8: =_xlfn.SINGLE(_xlfn.IFNA(VLOOKUP($U8,'פרטים אישיים'!$D$4:$G$100,4,FALSE),""))
J9: =_xlfn.SINGLE(_xlfn.IFNA(VLOOKUP($I9,'פרטים אישיים'!$D$4:$G$100,2,FALSE),"")) | K9: =_xlfn.SINGLE(_xlfn.IFNA(VLOOKUP($I9,'פרטים אישיים'!$D$4:$G$100,3,FALSE),"")) | L9: =_xlfn.SINGLE(_xlfn.IFNA(VLOOKUP($I9,'פרטים אישיים'!$D$4:$G$100,4,FALSE),"")) | P9: =_xlfn.SINGLE(_xlfn.IFNA(VLOOKUP($O9,'פרטים אישיים'!$D$4:$G$100,2,FALSE),"")) | Q9: =_xlfn.SINGLE(_xlfn.IFNA(VLOOKUP($O9,'פרטים אישיים'!$D$4:$G$100,3,FALSE),"")) | R9: =_xlfn.SINGLE(_xlfn.IFNA(VLOOKUP($O9,'פרטים אישיים'!$D$4:$G$100,4,FALSE),"")) | V9: =_xlfn.SINGLE(_xlfn.IFNA(VLOOKUP($U9,'פרטים אישיים'!$D$4:$G$100,2,FALSE),"")) | W9: =_xlfn.SINGLE(_xlfn.IFNA(VLOOKUP($U9,'פרטים אישיים'!$D$4:$G$100,3,FALSE),"")) | X9: =_xlfn.SINGLE(_xlfn.IFNA(VLOOKUP($U9,'פרטים אישיים'!$D$4:$G$100,4,FALSE),""))
J10: =_xlfn.SINGLE(_xlfn.IFNA(VLOOKUP($I10,'פרטים אישיים'!$D$4:$G$100,2,FALSE),"")) | K10: =_xlfn.SINGLE(_xlfn.IFNA(VLOOKUP($I10,'פרטים אישיים'!$D$4:$G$100,3,FALSE),"")) | L10: =_xlfn.SINGLE(_xlfn.IFNA(VLOOKUP($I10,'פרטים אישיים'!$D$4:$G$100,4,FALSE),"")) | S10: [מחר בבוקר] | T10: 05-07 (בונקר) | V10: =_xlfn.SINGLE(_xlfn.IFNA(VLOOKUP($U10,'פרטים אישיים'!$D$4:$G$100,2,FALSE),"")) | W10: =_xlfn.SINGLE(_xlfn.IFNA(VLOOKUP($U10,'פרטים אישיים'!$D$4:$G$100,3,FALSE),"")) | X10: =_xlfn.SINGLE(_xlfn.IFNA(VLOOKUP($U10,'פרטים אישיים'!$D$4:$G$100,4,FALSE),""))
C11: סיור ערב 15:00-23:00 | J11: =_xlfn.SINGLE(_xlfn.IFNA(VLOOKUP($I11,'פרטים אישיים'!$D$4:$G$100,2,FALSE),"")) | K11: =_xlfn.SINGLE(_xlfn.IFNA(VLOOKUP($I11,'פרטים אישיים'!$D$4:$G$100,3,FALSE),"")) | L11: =_xlfn.SINGLE(_xlfn.IFNA(VLOOKUP($I11,'פרטים אישיים'!$D$4:$G$100,4,FALSE),"")) | T11: 46272 | V11: =_xlfn.SINGLE(_xlfn.IFNA(VLOOKUP($U11,'פרטים אישיים'!$D$4:$G$100,2,FALSE),"")) | W11: =_xlfn.SINGLE(_xlfn.IFNA(VLOOKUP($U11,'פרטים אישיים'!$D$4:$G$100,3,FALSE),"")) | X11: =_xlfn.SINGLE(_xlfn.IFNA(VLOOKUP($U11,'פרטים אישיים'!$D$4:$G$100,4,FALSE),""))
C12: שם: | D12: פלאפון: | E12: מ.א. | F12: תפקיד: | J12: =_xlfn.SINGLE(_xlfn.IFNA(VLOOKUP($I12,'פרטים אישיים'!$D$4:$G$100,2,FALSE),"")) | K12: =_xlfn.SINGLE(_xlfn.IFNA(VLOOKUP($I12,'פרטים אישיים'!$D$4:$G$100,3,FALSE),"")) | L12: =_xlfn.SINGLE(_xlfn.IFNA(VLOOKUP($I12,'פרטים אישיים'!$D$4:$G$100,4,FALSE),"")) | T12: 46335 | V12: =_xlfn.SINGLE(_xlfn.IFNA(VLOOKUP($U12,'פרטים אישיים'!$D$4:$G$100,2,FALSE),"")) | W12: =_xlfn.SINGLE(_xlfn.IFNA(VLOOKUP($U12,'פרטים אישיים'!$D$4:$G$100,3,FALSE),"")) | X12: =_xlfn.SINGLE(_xlfn.IFNA(VLOOKUP($U12,'פרטים אישיים'!$D$4:$G$100,4,FALSE),""))
D13: =_xlfn.SINGLE(_xlfn.IFNA(VLOOKUP($C13,'פרטים אישיים'!$D$4:$G$100,2,FALSE),"")) | E13: =_xlfn.SINGLE(_xlfn.IFNA(VLOOKUP($C13,'פרטים אישיים'!$D$4:$G$100,3,FALSE),"")) | F13: =_xlfn.SINGLE(_xlfn.IFNA(VLOOKUP($C13,'פרטים אישיים'!$D$4:$G$100,4,FALSE),"")) | J13: =_xlfn.SINGLE(_xlfn.IFNA(VLOOKUP($I13,'פרטים אישיים'!$D$4:$G$100,2,FALSE),"")) | K13: =_xlfn.SINGLE(_xlfn.IFNA(VLOOKUP($I13,'פרטים אישיים'!$D$4:$G$100,3,FALSE),"")) | L13: =_xlfn.SINGLE(_xlfn.IFNA(VLOOKUP($I13,'פרטים אישיים'!$D$4:$G$100,4,FALSE),"")) | O13: גרשון | T13: 11-13 | V13: =_xlfn.SINGLE(_xlfn.IFNA(VLOOKUP($U13,'פרטים אישיים'!$D$4:$G$100,2,FALSE),"")) | W13: =_xlfn.SINGLE(_xlfn.IFNA(VLOOKUP($U13,'פרטים אישיים'!$D$4:$G$100,3,FALSE),"")) | X13: =_xlfn.SINGLE(_xlfn.IFNA(VLOOKUP($U13,'פרטים אישיים'!$D$4:$G$100,4,FALSE),""))
D14: =_xlfn.SINGLE(_xlfn.IFNA(VLOOKUP($C14,'פרטים אישיים'!$D$4:$G$100,2,FALSE),"")) | E14: =_xlfn.SINGLE(_xlfn.IFNA(VLOOKUP($C14,'פרטים אישיים'!$D$4:$G$100,3,FALSE),"")) | F14: =_xlfn.SINGLE(_xlfn.IFNA(VLOOKUP($C14,'פרטים אישיים'!$D$4:$G$100,4,FALSE),"")) | O14: שם: | P14: פלאפון: | Q14: מ.א. | R14: תפקיד:
D15: =_xlfn.SINGLE(_xlfn.IFNA(VLOOKUP($C15,'פרטים אישיים'!$D$4:$G$100,2,FALSE),"")) | E15: =_xlfn.SINGLE(_xlfn.IFNA(VLOOKUP($C15,'פרטים אישיים'!$D$4:$G$100,3,FALSE),"")) | F15: =_xlfn.SINGLE(_xlfn.IFNA(VLOOKUP($C15,'פרטים אישיים'!$D$4:$G$100,4,FALSE),"")) | P15: =_xlfn.SINGLE(_xlfn.IFNA(VLOOKUP($O15,'פרטים אישיים'!$D$4:$G$100,2,FALSE),"")) | Q15: =_xlfn.SINGLE(_xlfn.IFNA(VLOOKUP($O15,'פרטים אישיים'!$D$4:$G$100,3,FALSE),"")) | R15: =_xlfn.SINGLE(_xlfn.IFNA(VLOOKUP($O15,'פרטים אישיים'!$D$4:$G$100,4,FALSE),""))
I16: כרמל ב | P16: =_xlfn.SINGLE(_xlfn.IFNA(VLOOKUP($O16,'פרטים אישיים'!$D$4:$G$100,2,FALSE),"")) | Q16: =_xlfn.SINGLE(_xlfn.IFNA(VLOOKUP($O16,'פרטים אישיים'!$D$4:$G$100,3,FALSE),"")) | R16: =_xlfn.SINGLE(_xlfn.IFNA(VLOOKUP($O16,'פרטים אישיים'!$D$4:$G$100,4,FALSE),""))
I17: שם: | J17: פלאפון: | K17: מ.א. | L17: תפקיד: | P17: =_xlfn.SINGLE(_xlfn.IFNA(VLOOKUP($O17,'פרטים אישיים'!$D$4:$G$100,2,FALSE),"")) | Q17: =_xlfn.SINGLE(_xlfn.IFNA(VLOOKUP($O17,'פרטים אישיים'!$D$4:$G$100,3,FALSE),"")) | R17: =_xlfn.SINGLE(_xlfn.IFNA(VLOOKUP($O17,'פרטים אישיים'!$D$4:$G$100,4,FALSE),"")) | U17: תורנים
C18: סיור לילה 23:00-07:00 | J18: =_xlfn.SINGLE(_xlfn.IFNA(VLOOKUP($I18,'פרטים אישיים'!$D$4:$G$100,2,FALSE),"")) | K18: =_xlfn.SINGLE(_xlfn.IFNA(VLOOKUP($I18,'פרטים אישיים'!$D$4:$G$100,3,FALSE),"")) | L18: =_xlfn.SINGLE(_xlfn.IFNA(VLOOKUP($I18,'פרטים אישיים'!$D$4:$G$100,4,FALSE),"")) | P18: =_xlfn.SINGLE(_xlfn.IFNA(VLOOKUP($O18,'פרטים אישיים'!$D$4:$G$100,2,FALSE),"")) | Q18: =_xlfn.SINGLE(_xlfn.IFNA(VLOOKUP($O18,'פרטים אישיים'!$D$4:$G$100,3,FALSE),"")) | R18: =_xlfn.SINGLE(_xlfn.IFNA(VLOOKUP($O18,'פרטים אישיים'!$D$4:$G$100,4,FALSE),"")) | U18: שם: | V18: פלאפון: | W18: מ.א. | X18: תפקיד:
C19: שם: | D19: פלאפון: | E19: מ.א. | F19: תפקיד: | J19: =_xlfn.SINGLE(_xlfn.IFNA(VLOOKUP($I19,'פרטים אישיים'!$D$4:$G$100,2,FALSE),"")) | K19: =_xlfn.SINGLE(_xlfn.IFNA(VLOOKUP($I19,'פרטים אישיים'!$D$4:$G$100,3,FALSE),"")) | L19: =_xlfn.SINGLE(_xlfn.IFNA(VLOOKUP($I19,'פרטים אישיים'!$D$4:$G$100,4,FALSE),"")) | P19: =_xlfn.SINGLE(_xlfn.IFNA(VLOOKUP($O19,'פרטים אישיים'!$D$4:$G$100,2,FALSE),"")) | Q19: =_xlfn.SINGLE(_xlfn.IFNA(VLOOKUP($O19,'פרטים אישיים'!$D$4:$G$100,3,FALSE),"")) | R19: =_xlfn.SINGLE(_xlfn.IFNA(VLOOKUP($O19,'פרטים אישיים'!$D$4:$G$100,4,FALSE),"")) | T19: מטבח: | V19: =_xlfn.SINGLE(_xlfn.IFNA(VLOOKUP($U19,'פרטים אישיים'!$D$4:$G$100,2,FALSE),"")) | W19: =_xlfn.SINGLE(_xlfn.IFNA(VLOOKUP($U19,'פרטים אישיים'!$D$4:$G$100,3,FALSE),"")) | X19: =_xlfn.SINGLE(_xlfn.IFNA(VLOOKUP($U19,'פרטים אישיים'!$D$4:$G$100,4,FALSE),""))
C20: מאיר יוסט | D20: =_xlfn.SINGLE(_xlfn.IFNA(VLOOKUP($C20,'פרטים אישיים'!$D$4:$G$100,2,FALSE),"")) -> 058-6644228 | E20: =_xlfn.SINGLE(_xlfn.IFNA(VLOOKUP($C20,'פרטים אישיים'!$D$4:$G$100,3,FALSE),"")) -> 8264943 | F20: =_xlfn.SINGLE(_xlfn.IFNA(VLOOKUP($C20,'פרטים אישיים'!$D$4:$G$100,4,FALSE),"")) -> מ"מ | J20: =_xlfn.SINGLE(_xlfn.IFNA(VLOOKUP($I20,'פרטים אישיים'!$D$4:$G$100,2,FALSE),"")) | K20: =_xlfn.SINGLE(_xlfn.IFNA(VLOOKUP($I20,'פרטים אישיים'!$D$4:$G$100,3,FALSE),"")) | L20: =_xlfn.SINGLE(_xlfn.IFNA(VLOOKUP($I20,'פרטים אישיים'!$D$4:$G$100,4,FALSE),"")) | P20: =_xlfn.SINGLE(_xlfn.IFNA(VLOOKUP($O20,'פרטים אישיים'!$D$4:$G$100,2,FALSE),"")) | Q20: =_xlfn.SINGLE(_xlfn.IFNA(VLOOKUP($O20,'פרטים אישיים'!$D$4:$G$100,3,FALSE),"")) | R20: =_xlfn.SINGLE(_xlfn.IFNA(VLOOKUP($O20,'פרטים אישיים'!$D$4:$G$100,4,FALSE),"")) | T20: מפלג: | V20: =_xlfn.SINGLE(_xlfn.IFNA(VLOOKUP($U20,'פרטים אישיים'!$D$4:$G$100,2,FALSE),"")) | W20: =_xlfn.SINGLE(_xlfn.IFNA(VLOOKUP($U20,'פרטים אישיים'!$D$4:$G$100,3,FALSE),"")) | X20: =_xlfn.SINGLE(_xlfn.IFNA(VLOOKUP($U20,'פרטים אישיים'!$D$4:$G$100,4,FALSE),""))
D21: =_xlfn.SINGLE(_xlfn.IFNA(VLOOKUP($C21,'פרטים אישיים'!$D$4:$G$100,2,FALSE),"")) | E21: =_xlfn.SINGLE(_xlfn.IFNA(VLOOKUP($C21,'פרטים אישיים'!$D$4:$G$100,3,FALSE),"")) | F21: =_xlfn.SINGLE(_xlfn.IFNA(VLOOKUP($C21,'פרטים אישיים'!$D$4:$G$100,4,FALSE),"")) | J21: =_xlfn.SINGLE(_xlfn.IFNA(VLOOKUP($I21,'פרטים אישיים'!$D$4:$G$100,2,FALSE),"")) | K21: =_xlfn.SINGLE(_xlfn.IFNA(VLOOKUP($I21,'פרטים אישיים'!$D$4:$G$100,3,FALSE),"")) | L21: =_xlfn.SINGLE(_xlfn.IFNA(VLOOKUP($I21,'פרטים אישיים'!$D$4:$G$100,4,FALSE),""))
D22: =_xlfn.SINGLE(_xlfn.IFNA(VLOOKUP($C22,'פרטים אישיים'!$D$4:$G$100,2,FALSE),"")) | E22: =_xlfn.SINGLE(_xlfn.IFNA(VLOOKUP($C22,'פרטים אישיים'!$D$4:$G$100,3,FALSE),"")) | F22: =_xlfn.SINGLE(_xlfn.IFNA(VLOOKUP($C22,'פרטים אישיים'!$D$4:$G$100,4,FALSE),""))

Sheet טלפונים חשובים
C3: שם: | D3: טלפון:
C4: חמ"ל פלוגת אליעד | D4: 04-6674202
C5: חמ"ל גדוד | D5: 04-6674201
C9: רבש"צ אליעד | D9: 050-7881604
C10: שער אליעד | D10: 050-8109801
C12: רבש"צ אבני איתן | D12: 054-7725650
C13: שער אבני איתן | D13: 050-4750573
C15: רבש"צ מיצר | D15: 052-4576071
C16: שער מיצר | D16: 052-4185453
C18: רבש"צ מבוא חמה | D18: 052-6697460
C19: שער מבוא חמה | D19: 050-4750535
C21: רבש"צ כפר חרוב | D21: 054-5676830
... C37: שער בני יהודה | D37: אין שער

Sheet פרטים אישיים
C3: מחלקה | D3: שם | E3: פלאפון | F3: מ.א. | G3: תפקיד
C4: 1 | D4: מאיר יוסט | E4: 058-6644228 | F4: 8264943 | G4: מ"מ
C5: 1 | D5: חגי רובינשטיין | E5: 052-6469548 | F5: 8426106 | G5: סמל
C6: 1 | D6: דניאל דהן | E6: 050-2765495 | F6: 8495138 | G6: קלע
C7: 1 | D7: שחר בוחבוט | E7: 054-6979195 | F7: 8119530 | G7: לוחם
C8: 1 | D8: עמית חורש | E8: 052-4798833 | F8: 8470988 | G8: חובש
C9: 1 | D9: נתנאל שלום | E9: 054-6406758 | F9: 8459664 | G9: לוחם
C10: 1 | D10: חי בראשי | E10: 052-5099924 | F10: 8457250 | G10: לוחם
C11: 1 | D11: מאור לבקוביץ' | E11: 054-2100179 | F11: 8113920 | G11: לוחם
C12: 1 | D12: מיכאל ירט | E12: 054-9147809 | F12: 8434696 | G12: חובש
C13: 1 | D13: יאיר שוייצר | E13: 052-3909856 | F13: 8233128 | G13: קלע
C14: 1 | D14: אריאל וילנר | E14: 052-2456636 | F14: 8110205 | G14: לוחם
C15: 1 | D15: אביתר בן-שושן | E15: 053-5251353 | F15: 8301564 | G15: לוחם
... C37: 2 | D37: חיים חשדי | E37: 050-9355978 | F37: 8279507 | G37: לוחם
C38: 2 | D38: בקא ינקילוביץ | F38: 8501127
C39: 2 | D39: אוריה כהן | E39: 054-7090523 | F39: 8476129 | G39: לוחם
C40: 2 | D40: גיל כהן | E40: 052-4732508 | F40: 8346206 | G40: לוחם
C41: 2 | D41: עידו גלאי | E41: 054-9104484 | F41: 8528026 | G41: לוחם
C42: 2 | D42: נאור חורי | E42: 052-8400735 | F42: 8307026 | G42: חובש
C43: 2 | D43: רועי שטרן | E43: 050-4229066 | F43: 8061709 | G43: לוחם
C44: 3 | D44: שלמה אנטופולסקי | E44: 053-4254772 | F44: 8787682
C45: 3 | D45: אהרון כהן | E45: 058-5782828 | F45: 8734756
C46: 3 | D46: פרץ האוקיפ | E46: 053-2246258 | F46: 9174639
C47: 3 | D47: שמואל חונגסאי | E47: 053-8585307 | F47: 9308005
C48: 3 | D48: אור שימרון | E48: 050-3231603 | F48: 8817559
C49: 3 | D49: יהודה האוקיפ | E49: 055-6841199 | F49: 9174430
C50: 3 | D50: נווה כהן | E50: 058-7780570 | F50: 8811699
C51: 3 | D51: יצחק ביטון | E51: 050-2190035 | F51: 8806762
C52: 3 | D52: אלחנן שפירא | E52: 058-4771731 | F52: 8752855
C53: 3 | D53: ערן ברקוביץ | E53: 050-2556665 | F53: 7303735
C54: 3 | D54: יואל רוביני | E54: 052-7570735 | F54: 7526152
C55: 3 | D55: יצחק ארניאס | E55: 050-8619549 | F55: 8537190
... C72: 3 | D72: שרון גוילי | E72: 050-9323226 | F72: 7534869
C76: מפל"ג | D76: יעקב ביטון | E76: 052-5558204 | F76: 7289435
C77: מפל"ג | D77: ניר לוסטיג | E77: 058-6633010 | F77: 8009927
C78: מפל"ג | D78: טאי ארזואן | E78: 054-9437255 | F78: 8192692
C79: מפל"ג | D79: שניר שילוח | E79: 054-2599896 | F79: 8190180
C80: מפל"ג | D80: עידן חדד | E80: 053-6246517 | F80: 7490572
C81: מפל"ג | D81: יגאל שטיינמיץ | F81: 8499480
C82: מפל"ג | D82: יכין בן אברהם | E82: 052-7362259 | F82: 7534927
...
